Workbook

Sheet Student Data
A1: SUNSHINE PUBLIC SCHOOL – Student Database | 2024-25
A2: Student ID | B2: First Name | C2: Last Name | D2: Date of Birth | E2: Gender | F2: Grade | G2: Section | H2: Math | I2: Science | J2: English | K2: Hindi | L2: Attendance % | M2: Fee Status
A3: SCH2024001 | B3: Ishaan | C3: Reddy | D3: 40741 | E3: M | F3: 7 | G3: C | H3: 51 | I3: 52 | J3: 57 | K3: 48 | L3: 89.6 | M3: Paid
A4: SCH2024002 | B4: Tanya | C4: Verma | D4: 39626 | E4: F | F4: 10 | G4: B | H4: 52 | I4: 64 | J4: 88 | K4: 79 | L4: 82.9 | M4: Pending
A5: SCH2024003 | B5: Ishaan | C5: Gupta | D5: 40808 | E5: M | F5: 7 | G5: B | H5: 82 | I5: 49 | J5: 96 | K5: 76 | L5: 73.2 | M5: Partial
A6: SCH2024004 | B6: Ananya | C6: Chopra | D6: 40424 | E6: F | F6: 8 | G6: B | H6: 42 | I6: 55 | J6: 77 | K6: 40 | L6: 76.6 | M6: Paid
A7: SCH2024005 | B7: Rahul | C7: Khanna | D7: 40883 | E7: M | F7: 7 | G7: C | H7: 69 | I7: 100 | J7: 45 | K7: 62 | L7: 65 | M7: Partial
A8: SCH2024006 | B8: Kriti | C8: Bose | D8: 40727 | E8: F | F8: 7 | G8: C | H8: 82 | I8: 49 | J8: 44 | K8: 47 | L8: 60.9 | M8: Paid
A9: SCH2024007 | B9: Varun | C9: Verma | D9: 40564 | E9: M | F9: 7 | G9: B | H9: 79 | I9: 38 | J9: 66 | K9: 61 | L9: 65.3 | M9: Paid
A10: SCH2024008 | B10: Shreya | C10: Malhotra | D10: 40183 | E10: F | F10: 8 | G10: C | H10: 65 | I10: 90 | J10: 90 | K10: 48 | L10: 73.8 | M10: Pending
A11: SCH2024009 | B11: Kunal | C11: Mehta | D11: 39634 | E11: M | F11: 10 | G11: B | H11: 47 | I11: 44 | J11: 49 | K11: 49 | L11: 71.5 | M11: Partial
A12: SCH2024010 | B12: Shreya | C12: Tiwari | D12: 40259 | E12: F | F12: 8 | G12: B | H12: 91 | I12: 52 | J12: 96 | K12: 56 | L12: 64.6 | M12: Partial
A13: SCH2024011 | B13: Arjun | C13: Khanna | D13: 40372 | E13: M | F13: 8 | G13: A | H13: 77 | I13: 91 | J13: 45 | K13: 61 | L13: 68.4 | M13: Paid
A14: SCH2024012 | B14: Diya | C14: Nair | D14: 39668 | E14: F | F14: 10 | G14: A | H14: 51 | I14: 94 | J14: 44 | K14: 99 | L14: 74.5 | M14: Partial
... A52: SCH2024050 | B52: Simran | C52: Tiwari | D52: 40186 | E52: F | F52: 8 | G52: B | H52: 85 | I52: 60 | J52: 93 | K52: 47 | L52: 70.7 | M52: Paid

Sheet Formulas
A1: VLOOKUP | INDEX-MATCH | IF | Nested Functions
A3: MARKS TABLE (used as lookup)
A4: Student ID | B4: Name | C4: Grade | D4: Math | E4: Science | F4: English | G4: Total | H4: Percentage
A5: SCH2024001 | B5: Ishaan Reddy | C5: 7 | D5: 51 | E5: 52 | F5: 57 | G5: =SUM(D5:F5) -> 160 | H5: =ROUND(G5/300*100,1) -> 53.3
A6: SCH2024002 | B6: Tanya Verma | C6: 10 | D6: 52 | E6: 64 | F6: 88 | G6: =SUM(D6:F6) -> 204 | H6: =ROUND(G6/300*100,1) -> 68
A7: SCH2024003 | B7: Ishaan Gupta | C7: 7 | D7: 82 | E7: 49 | F7: 96 | G7: =SUM(D7:F7) -> 227 | H7: =ROUND(G7/300*100,1) -> 75.7
A8: SCH2024004 | B8: Ananya Chopra | C8: 8 | D8: 42 | E8: 55 | F8: 77 | G8: =SUM(D8:F8) -> 174 | H8: =ROUND(G8/300*100,1) -> 58
A9: SCH2024005 | B9: Rahul Khanna | C9: 7 | D9: 69 | E9: 100 | F9: 45 | G9: =SUM(D9:F9) -> 214 | H9: =ROUND(G9/300*100,1) -> 71.3
A10: SCH2024006 | B10: Kriti Bose | C10: 7 | D10: 82 | E10: 49 | F10: 44 | G10: =SUM(D10:F10) -> 175 | H10: =ROUND(G10/300*100,1) -> 58.3
A11: SCH2024007 | B11: Varun Verma | C11: 7 | D11: 79 | E11: 38 | F11: 66 | G11: =SUM(D11:F11) -> 183 | H11: =ROUND(G11/300*100,1) -> 61
A12: SCH2024008 | B12: Shreya Malhotra | C12: 8 | D12: 65 | E12: 90 | F12: 90 | G12: =SUM(D12:F12) -> 245 | H12: =ROUND(G12/300*100,1) -> 81.7
A13: SCH2024009 | B13: Kunal Mehta | C13: 10 | D13: 47 | E13: 44 | F13: 49 | G13: =SUM(D13:F13) -> 140 | H13: =ROUND(G13/300*100,1) -> 46.7
A14: SCH2024010 | B14: Shreya Tiwari | C14: 8 | D14: 91 | E14: 52 | F14: 96 | G14: =SUM(D14:F14) -> 239 | H14: =ROUND(G14/300*100,1) -> 79.7
A15: SCH2024011 | B15: Arjun Khanna | C15: 8 | D15: 77 | E15: 91 | F15: 45 | G15: =SUM(D15:F15) -> 213 | H15: =ROUND(G15/300*100,1) -> 71
A16: SCH2024012 | B16: Diya Nair | C16: 10 | D16: 51 | E16: 94 | F16: 44 | G16: =SUM(D16:F16) -> 189 | H16: =ROUND(G16/300*100,1) -> 63
... A44: SCH2024040 | B44: Kriti Verma | C44: 7 | D44: 54 | E44: 59 | F44: 69 | G44: =SUM(D44:F44) -> 182 | H44: =ROUND(G44/300*100,1) -> 60.7
A47: VLOOKUP
A48: Type ID here | B48: SCH2024001
A49: Student Name | B49: =IFERROR(VLOOKUP(B48,A5:H44,2,FALSE()),"Not found") -> Ishaan Reddy
A50: Grade | B50: =IFERROR(VLOOKUP(B48,A5:H44,3,FALSE()),"Not found") -> 7
A51: Math Marks | B51: =IFERROR(VLOOKUP(B48,A5:H44,4,FALSE()),"Not found") -> 51
A52: Total Marks | B52: =IFERROR(VLOOKUP(B48,A5:H44,7,FALSE()),"Not found") -> 160
A53: Percentage | B53: =IFERROR(VLOOKUP(B48,A5:H44,8,FALSE()),"Not found") -> 53.3
A56: INDEX-MATCH
A57: Student Name | B57: Kriti Bose
A58: Science Marks | B58: =IFERROR(INDEX(E5:E44,MATCH(B57,B5:B44,0)),"Not found") -> 49
A61: IF & NESTED IF
A62: Student ID | B62: Name | C62: Percentage | D62: Grade Letter | E62: Pass / Fail | F62: Remark
A63: SCH2024001 | B63: Ishaan Reddy | C63: =IFERROR(VLOOKUP(A63,A5:H44,8,FALSE()),0) -> 53.3 | D63: =IF(C63>=90,"A+",IF(C63>=75,"A",IF(C63>=60,"B",IF(C63>=45,"C","D")))) -> C | E63: =IF(C63>=33,"PASS","FAIL") -> PASS | F63: =IF(C63>=90,"Excellent",IF(C63>=75,"Very Good",IF(C63>=60,"Good",IF(C63>=45,"Average","Needs Improvement")))) -> Average
A64: SCH2024002 | B64: Tanya Verma | C64: =IFERROR(VLOOKUP(A64,A5:H44,8,FALSE()),0) -> 68 | D64: =IF(C64>=90,"A+",IF(C64>=75,"A",IF(C64>=60,"B",IF(C64>=45,"C","D")))) -> B | E64: =IF(C64>=33,"PASS","FAIL") -> PASS | F64: =IF(C64>=90,"Excellent",IF(C64>=75,"Very Good",IF(C64>=60,"Good",IF(C64>=45,"Average","Needs Improvement")))) -> Good
A65: SCH2024003 | B65: Ishaan Gupta | C65: =IFERROR(VLOOKUP(A65,A5:H44,8,FALSE()),0) -> 75.7 | D65: =IF(C65>=90,"A+",IF(C65>=75,"A",IF(C65>=60,"B",IF(C65>=45,"C","D")))) -> A | E65: =IF(C65>=33,"PASS","FAIL") -> PASS | F65: =IF(C65>=90,"Excellent",IF(C65>=75,"Very Good",IF(C65>=60,"Good",IF(C65>=45,"Average","Needs Improvement")))) -> Very Good
A66: SCH2024004 | B66: Ananya Chopra | C66: =IFERROR(VLOOKUP(A66,A5:H44,8,FALSE()),0) -> 58 | D66: =IF(C66>=90,"A+",IF(C66>=75,"A",IF(C66>=60,"B",IF(C66>=45,"C","D")))) -> C | E66: =IF(C66>=33,"PASS","FAIL") -> PASS | F66: =IF(C66>=90,"Excellent",IF(C66>=75,"Very Good",IF(C66>=60,"Good",IF(C66>=45,"Average","Needs Improvement")))) -> Average
A67: SCH2024005 | B67: Rahul Khanna | C67: =IFERROR(VLOOKUP(A67,A5:H44,8,FALSE()),0) -> 71.3 | D67: =IF(C67>=90,"A+",IF(C67>=75,"A",IF(C67>=60,"B",IF(C67>=45,"C","D")))) -> B | E67: =IF(C67>=33,"PASS","FAIL") -> PASS | F67: =IF(C67>=90,"Excellent",IF(C67>=75,"Very Good",IF(C67>=60,"Good",IF(C67>=45,"Average","Needs Improvement")))) -> Good
A68: SCH2024006 | B68: Kriti Bose | C68: =IFERROR(VLOOKUP(A68,A5:H44,8,FALSE()),0) -> 58.3 | D68: =IF(C68>=90,"A+",IF(C68>=75,"A",IF(C68>=60,"B",IF(C68>=45,"C","D")))) -> C | E68: =IF(C68>=33,"PASS","FAIL") -> PASS | F68: =IF(C68>=90,"Excellent",IF(C68>=75,"Very Good",IF(C68>=60,"Good",IF(C68>=45,"Average","Needs Improvement")))) -> Average
A69: SCH2024007 | B69: Varun Verma | C69: =IFERROR(VLOOKUP(A69,A5:H44,8,FALSE()),0) -> 61 | D69: =IF(C69>=90,"A+",IF(C69>=75,"A",IF(C69>=60,"B",IF(C69>=45,"C","D")))) -> B | E69: =IF(C69>=33,"PASS","FAIL") -> PASS | F69: =IF(C69>=90,"Excellent",IF(C69>=75,"Very Good",IF(C69>=60,"Good",IF(C69>=45,"Average","Needs Improvement")))) -> Good
A70: SCH2024008 | B70: Shreya Malhotra | C70: =IFERROR(VLOOKUP(A70,A5:H44,8,FALSE()),0) -> 81.7 | D70: =IF(C70>=90,"A+",IF(C70>=75,"A",IF(C70>=60,"B",IF(C70>=45,"C","D")))) -> A | E70: =IF(C70>=33,"PASS","FAIL") -> PASS | F70: =IF(C70>=90,"Excellent",IF(C70>=75,"Very Good",IF(C70>=60,"Good",IF(C70>=45,"Average","Needs Improvement")))) -> Very Good
A71: SCH2024009 | B71: Kunal Mehta | C71: =IFERROR(VLOOKUP(A71,A5:H44,8,FALSE()),0) -> 46.7 | D71: =IF(C71>=90,"A+",IF(C71>=75,"A",IF(C71>=60,"B",IF(C71>=45,"C","D")))) -> C | E71: =IF(C71>=33,"PASS","FAIL") -> PASS | F71: =IF(C71>=90,"Excellent",IF(C71>=75,"Very Good",IF(C71>=60,"Good",IF(C71>=45,"Average","Needs Improvement")))) -> Average
A72: SCH2024010 | B72: Shreya Tiwari | C72: =IFERROR(VLOOKUP(A72,A5:H44,8,FALSE()),0) -> 79.7 | D72: =IF(C72>=90,"A+",IF(C72>=75,"A",IF(C72>=60,"B",IF(C72>=45,"C","D")))) -> A | E72: =IF(C72>=33,"PASS","FAIL") -> PASS | F72: =IF(C72>=90,"Excellent",IF(C72>=75,"Very Good",IF(C72>=60,"Good",IF(C72>=45,"Average","Needs Improvement")))) -> Very Good
A73: SCH2024011 | B73: Arjun Khanna | C73: =IFERROR(VLOOKUP(A73,A5:H44,8,FALSE()),0) -> 71 | D73: =IF(C73>=90,"A+",IF(C73>=75,"A",IF(C73>=60,"B",IF(C73>=45,"C","D")))) -> B | E73: =IF(C73>=33,"PASS","FAIL") -> PASS | F73: =IF(C73>=90,"Excellent",IF(C73>=75,"Very Good",IF(C73>=60,"Good",IF(C73>=45,"Average","Needs Improvement")))) -> Good
A74: SCH2024012 | B74: Diya Nair | C74: =IFERROR(VLOOKUP(A74,A5:H44,8,FALSE()),0) -> 63 | D74: =IF(C74>=90,"A+",IF(C74>=75,"A",IF(C74>=60,"B",IF(C74>=45,"C","D")))) -> B | E74: =IF(C74>=33,"PASS","FAIL") -> PASS | F74: =IF(C74>=90,"Excellent",IF(C74>=75,"Very Good",IF(C74>=60,"Good",IF(C74>=45,"Average","Needs Improvement")))) -> Good
...

Sheet Conditional Formatting
A1: CONDITIONAL FORMATTING – Marks Highlighted by Performance
A2: Student ID | B2: Name | C2: Grade | D2: Math | E2: Science | F2: English | G2: Total | H2: Result
A3: SCH2024001 | B3: Ishaan Reddy | C3: 7 | D3: 51 | E3: 52 | F3: 57 | G3: =SUM(D3:F3) -> 160 | H3: =IF(G3/300*100>=33,"PASS","FAIL") -> PASS
A4: SCH2024002 | B4: Tanya Verma | C4: 10 | D4: 52 | E4: 64 | F4: 88 | G4: =SUM(D4:F4) -> 204 | H4: =IF(G4/300*100>=33,"PASS","FAIL") -> PASS
A5: SCH2024003 | B5: Ishaan Gupta | C5: 7 | D5: 82 | E5: 49 | F5: 96 | G5: =SUM(D5:F5) -> 227 | H5: =IF(G5/300*100>=33,"PASS","FAIL") -> PASS
A6: SCH2024004 | B6: Ananya Chopra | C6: 8 | D6: 42 | E6: 55 | F6: 77 | G6: =SUM(D6:F6) -> 174 | H6: =IF(G6/300*100>=33,"PASS","FAIL") -> PASS
A7: SCH2024005 | B7: Rahul Khanna | C7: 7 | D7: 69 | E7: 100 | F7: 45 | G7: =SUM(D7:F7) -> 214 | H7: =IF(G7/300*100>=33,"PASS","FAIL") -> PASS
A8: SCH2024006 | B8: Kriti Bose | C8: 7 | D8: 82 | E8: 49 | F8: 44 | G8: =SUM(D8:F8) -> 175 | H8: =IF(G8/300*100>=33,"PASS","FAIL") -> PASS
A9: SCH2024007 | B9: Varun Verma | C9: 7 | D9: 79 | E9: 38 | F9: 66 | G9: =SUM(D9:F9) -> 183 | H9: =IF(G9/300*100>=33,"PASS","FAIL") -> PASS
A10: SCH2024008 | B10: Shreya Malhotra | C10: 8 | D10: 65 | E10: 90 | F10: 90 | G10: =SUM(D10:F10) -> 245 | H10: =IF(G10/300*100>=33,"PASS","FAIL") -> PASS
A11: SCH2024009 | B11: Kunal Mehta | C11: 10 | D11: 47 | E11: 44 | F11: 49 | G11: =SUM(D11:F11) -> 140 | H11: =IF(G11/300*100>=33,"PASS","FAIL") -> PASS
A12: SCH2024010 | B12: Shreya Tiwari | C12: 8 | D12: 91 | E12: 52 | F12: 96 | G12: =SUM(D12:F12) -> 239 | H12: =IF(G12/300*100>=33,"PASS","FAIL") -> PASS
A13: SCH2024011 | B13: Arjun Khanna | C13: 8 | D13: 77 | E13: 91 | F13: 45 | G13: =SUM(D13:F13) -> 213 | H13: =IF(G13/300*100>=33,"PASS","FAIL") -> PASS
A14: SCH2024012 | B14: Diya Nair | C14: 10 | D14: 51 | E14: 94 | F14: 44 | G14: =SUM(D14:F14) -> 189 | H14: =IF(G14/300*100>=33,"PASS","FAIL") -> PASS
... A42: SCH2024040 | B42: Kriti Verma | C42: 7 | D42: 54 | E42: 59 | F42: 69 | G42: =SUM(D42:F42) -> 182 | H42: =IF(G42/300*100>=33,"PASS","FAIL") -> PASS

Sheet Charts
A1: DATA VISUALIZATION – Charts & Graphs
A3: Grade | B3: Students | C3: Avg Math
A4: Grade 6 | B4: =COUNTIF('Student Data'!F3:F52,6) -> 4 | C4: =IFERROR(ROUND(AVERAGEIF('Student Data'!F3:F52,6,'Student Data'!H3:H52),1),0) -> 59.3
A5: Grade 7 | B5: =COUNTIF('Student Data'!F3:F52,7) -> 16 | C5: =IFERROR(ROUND(AVERAGEIF('Student Data'!F3:F52,7,'Student Data'!H3:H52),1),0) -> 60.8
A6: Grade 8 | B6: =COUNTIF('Student Data'!F3:F52,8) -> 17 | C6: =IFERROR(ROUND(AVERAGEIF('Student Data'!F3:F52,8,'Student Data'!H3:H52),1),0) -> 74.1
A7: Grade 9 | B7: =COUNTIF('Student Data'!F3:F52,9) -> 5 | C7: =IFERROR(ROUND(AVERAGEIF('Student Data'!F3:F52,9,'Student Data'!H3:H52),1),0) -> 63.4
A8: Grade 10 | B8: =COUNTIF('Student Data'!F3:F52,10) -> 8 | C8: =IFERROR(ROUND(AVERAGEIF('Student Data'!F3:F52,10,'Student Data'!H3:H52),1),0) -> 62
A20: Fee Status | B20: Count
A21: Paid | B21: =COUNTIF('Student Data'!M3:M52,"Paid") -> 28
A22: Pending | B22: =COUNTIF('Student Data'!M3:M52,"Pending") -> 8
A23: Partial | B23: =COUNTIF('Student Data'!M3:M52,"Partial") -> 14

Sheet Table
A1: PIVOT TABLE ANALYSIS
A3: Pivot 1: Students by Grade × Section | G3: Pivot 2: Students by Grade × Fee Status
A4: Grade \ Section | B4: A | C4: B | D4: C | E4: Total | G4: Grade \ Fee | H4: Paid | I4: Pending | J4: Partial | K4: Total
A5: Grade 6 | B5: =COUNTIFS('Student Data'!F3:F52,6,'Student Data'!G3:G52,"A") -> 1 | C5: =COUNTIFS('Student Data'!F3:F52,6,'Student Data'!G3:G52,"B") -> 1 | D5: =COUNTIFS('Student Data'!F3:F52,6,'Student Data'!G3:G52,"C") -> 2 | E5: =SUM(B5:D5) -> 4 | G5: Grade 6 | H5: =COUNTIFS('Student Data'!F3:F52,6,'Student Data'!M3:M52,"Paid") -> 4 | I5: =COUNTIFS('Student Data'!F3:F52,6,'Student Data'!M3:M52,"Pending") -> 0 | J5: =COUNTIFS('Student Data'!F3:F52,6,'Student Data'!M3:M52,"Partial") -> 0 | K5: =SUM(H5:J5) -> 4
A6: Grade 7 | B6: =COUNTIFS('Student Data'!F3:F52,7,'Student Data'!G3:G52,"A") -> 0 | C6: =COUNTIFS('Student Data'!F3:F52,7,'Student Data'!G3:G52,"B") -> 7 | D6: =COUNTIFS('Student Data'!F3:F52,7,'Student Data'!G3:G52,"C") -> 9 | E6: =SUM(B6:D6) -> 16 | G6: Grade 7 | H6: =COUNTIFS('Student Data'!F3:F52,7,'Student Data'!M3:M52,"Paid") -> 9 | I6: =COUNTIFS('Student Data'!F3:F52,7,'Student Data'!M3:M52,"Pending") -> 1 | J6: =COUNTIFS('Student Data'!F3:F52,7,'Student Data'!M3:M52,"Partial") -> 6 | K6: =SUM(H6:J6) -> 16
A7: Grade 8 | B7: =COUNTIFS('Student Data'!F3:F52,8,'Student Data'!G3:G52,"A") -> 7 | C7: =COUNTIFS('Student Data'!F3:F52,8,'Student Data'!G3:G52,"B") -> 7 | D7: =COUNTIFS('Student Data'!F3:F52,8,'Student Data'!G3:G52,"C") -> 3 | E7: =SUM(B7:D7) -> 17 | G7: Grade 8 | H7: =COUNTIFS('Student Data'!F3:F52,8,'Student Data'!M3:M52,"Paid") -> 9 | I7: =COUNTIFS('Student Data'!F3:F52,8,'Student Data'!M3:M52,"Pending") -> 5 | J7: =COUNTIFS('Student Data'!F3:F52,8,'Student Data'!M3:M52,"Partial") -> 3 | K7: =SUM(H7:J7) -> 17
A8: Grade 9 | B8: =COUNTIFS('Student Data'!F3:F52,9,'Student Data'!G3:G52,"A") -> 1 | C8: =COUNTIFS('Student Data'!F3:F52,9,'Student Data'!G3:G52,"B") -> 1 | D8: =COUNTIFS('Student Data'!F3:F52,9,'Student Data'!G3:G52,"C") -> 3 | E8: =SUM(B8:D8) -> 5 | G8: Grade 9 | H8: =COUNTIFS('Student Data'!F3:F52,9,'Student Data'!M3:M52,"Paid") -> 3 | I8: =COUNTIFS('Student Data'!F3:F52,9,'Student Data'!M3:M52,"Pending") -> 0 | J8: =COUNTIFS('Student Data'!F3:F52,9,'Student Data'!M3:M52,"Partial") -> 2 | K8: =SUM(H8:J8) -> 5
A9: Grade 10 | B9: =COUNTIFS('Student Data'!F3:F52,10,'Student Data'!G3:G52,"A") -> 2 | C9: =COUNTIFS('Student Data'!F3:F52,10,'Student Data'!G3:G52,"B") -> 4 | D9: =COUNTIFS('Student Data'!F3:F52,10,'Student Data'!G3:G52,"C") -> 2 | E9: =SUM(B9:D9) -> 8 | G9: Grade 10 | H9: =COUNTIFS('Student Data'!F3:F52,10,'Student Data'!M3:M52,"Paid") -> 3 | I9: =COUNTIFS('Student Data'!F3:F52,10,'Student Data'!M3:M52,"Pending") -> 2 | J9: =COUNTIFS('Student Data'!F3:F52,10,'Student Data'!M3:M52,"Partial") -> 3 | K9: =SUM(H9:J9) -> 8
A10: TOTAL | B10: =SUM(B5:B9) -> 11 | C10: =SUM(C5:C9) -> 20 | D10: =SUM(D5:D9) -> 19 | E10: =SUM(E5:E9) -> 50 | G10: TOTAL | H10: =SUM(H5:H9) -> 28 | I10: =SUM(I5:I9) -> 8 | J10: =SUM(J5:J9) -> 14 | K10: =SUM(K5:K9) -> 50

Sheet Dashboard
A1: SUNSHINE PUBLIC SCHOOL – Student Dashboard | 2024-25
A3: Total Students | C3: Paid Fees | E3: Fee Pending | G3: Avg Attendance
A4: =COUNTA('Student Data'!A3:A52) -> 50 | C4: =COUNTIF('Student Data'!M3:M52,"Paid") -> 28 | E4: =COUNTIF('Student Data'!M3:M52,"Pending") -> 8 | G4: =ROUND(AVERAGE('Student Data'!L3:L52),1) -> 77.4
A7: Grade-wise Summary | G7: Fee Status Summary
A8: Grade | B8: Total | C8: Boys | D8: Girls | E8: Avg Attendance | G8: Status | H8: Count | I8: % of Total
A9: 6 | B9: =COUNTIF('Student Data'!F3:F52,6) -> 4 | C9: =COUNTIFS('Student Data'!F3:F52,6,'Student Data'!E3:E52,"M") -> 1 | D9: =COUNTIFS('Student Data'!F3:F52,6,'Student Data'!E3:E52,"F") -> 3 | E9: =IFERROR(ROUND(AVERAGEIF('Student Data'!F3:F52,6,'Student Data'!L3:L52),1),0) -> 84.8 | G9: Paid | H9: =COUNTIF('Student Data'!M3:M52,"Paid") -> 28 | I9: =IFERROR(ROUND(H9/COUNTA('Student Data'!M3:M52)*100,1),0) -> 56
A10: 7 | B10: =COUNTIF('Student Data'!F3:F52,7) -> 16 | C10: =COUNTIFS('Student Data'!F3:F52,7,'Student Data'!E3:E52,"M") -> 9 | D10: =COUNTIFS('Student Data'!F3:F52,7,'Student Data'!E3:E52,"F") -> 7 | E10: =IFERROR(ROUND(AVERAGEIF('Student Data'!F3:F52,7,'Student Data'!L3:L52),1),0) -> 74.8 | G10: Pending | H10: =COUNTIF('Student Data'!M3:M52,"Pending") -> 8 | I10: =IFERROR(ROUND(H10/COUNTA('Student Data'!M3:M52)*100,1),0) -> 16
A11: 8 | B11: =COUNTIF('Student Data'!F3:F52,8) -> 17 | C11: =COUNTIFS('Student Data'!F3:F52,8,'Student Data'!E3:E52,"M") -> 7 | D11: =COUNTIFS('Student Data'!F3:F52,8,'Student Data'!E3:E52,"F") -> 10 | E11: =IFERROR(ROUND(AVERAGEIF('Student Data'!F3:F52,8,'Student Data'!L3:L52),1),0) -> 76.6 | G11: Partial | H11: =COUNTIF('Student Data'!M3:M52,"Partial") -> 14 | I11: =IFERROR(ROUND(H11/COUNTA('Student Data'!M3:M52)*100,1),0) -> 28
A12: 9 | B12: =COUNTIF('Student Data'!F3:F52,9) -> 5 | C12: =COUNTIFS('Student Data'!F3:F52,9,'Student Data'!E3:E52,"M") -> 3 | D12: =COUNTIFS('Student Data'!F3:F52,9,'Student Data'!E3:E52,"F") -> 2 | E12: =IFERROR(ROUND(AVERAGEIF('Student Data'!F3:F52,9,'Student Data'!L3:L52),1),0) -> 77.2
A13: 10 | B13: =COUNTIF('Student Data'!F3:F52,10) -> 8 | C13: =COUNTIFS('Student Data'!F3:F52,10,'Student Data'!E3:E52,"M") -> 5 | D13: =COUNTIFS('Student Data'!F3:F52,10,'Student Data'!E3:E52,"F") -> 3 | E13: =IFERROR(ROUND(AVERAGEIF('Student Data'!F3:F52,10,'Student Data'!L3:L52),1),0) -> 80.8
