Workbook
Name Data_Intelligence: Table1[]
Name Slicer_Category: #N/A
Name Slicer_Customer_Segment: #N/A
Name Slicer_Months__Date: #N/A
Name Slicer_Payment_Method: #N/A
Name Slicer_Region: #N/A
Name Slicer_Years__Date: #N/A

Sheet Dataset
A1: Transaction_ID | B1: Date | C1: Customer_ID | D1: Customer_Name | E1: Product_ID | F1: Product_Name | G1: Category | H1: Quantity | I1: Unit_Price | J1: Payment_Method | K1: Region | L1: Customer_Segment | M1: Customer_Since | N1: Total_Amount
A2: TRX0050 | B2: 45740 | C2: CUST001 | D2: John Smith | E2: P008 | F2: Bookshelf | G2: Furniture | H2: 4 | I2: 149.99 | J2: PayPal | K2: West | L2: Standard | M2: 44560 | N2: 599.96
A3: TRX0130 | B3: 45430 | C3: CUST002 | D3: Emma Wilson | E3: P008 | F3: Bookshelf | G3: Furniture | H3: 3 | I3: 149.99 | J3: Credit Card | K3: West | L3: Premium | M3: 45068 | N3: 449.97
A4: TRX0096 | B4: 45474 | C4: CUST002 | D4: Emma Wilson | E4: P010 | F4: Keyboard | G4: Electronics | H4: 2 | I4: 89.99 | J4: PayPal | K4: Central | L4: Premium | M4: 45275 | N4: 179.98
A5: TRX0142 | B5: 45544 | C5: CUST002 | D5: Emma Wilson | E5: P005 | F5: Blender | G5: Appliances | H5: 3 | I5: 59.99 | J5: PayPal | K5: East | L5: Standard | M5: 44748 | N5: 179.97
A6: TRX0028 | B6: 45644 | C6: CUST002 | D6: Emma Wilson | E6: P005 | F6: Blender | G6: Appliances | H6: 2 | I6: 59.99 | J6: Cash | K6: West | L6: Basic | M6: 45191 | N6: 119.98
A7: TRX0003 | B7: 45737 | C7: CUST002 | D7: Emma Wilson | E7: P008 | F7: Bookshelf | G7: Furniture | H7: 2 | I7: 149.99 | J7: Cash | K7: West | L7: Premium | M7: 45233 | N7: 299.98
A8: TRX0212 | B8: 45400 | C8: CUST003 | D8: Michael Brown | E8: P008 | F8: Bookshelf | G8: Furniture | H8: 5 | I8: 149.99 | J8: Credit Card | K8: North | L8: Premium | M8: 45295 | N8: 749.95
A9: TRX0220 | B9: 45450 | C9: CUST003 | D9: Michael Brown | E9: P008 | F9: Bookshelf | G9: Furniture | H9: 2 | I9: 149.99 | J9: Cash | K9: East | L9: Premium | M9: 44645 | N9: 299.98
A10: TRX0113 | B10: 45481 | C10: CUST003 | D10: Michael Brown | E10: P002 | F10: Smartphone | G10: Electronics | H10: 2 | I10: 699.99 | J10: PayPal | K10: East | L10: Premium | M10: 45389 | N10: 1399.98
A11: TRX0174 | B11: 45566 | C11: CUST003 | D11: Michael Brown | E11: P007 | F11: Desk | G11: Furniture | H11: 4 | I11: 299.99 | J11: Cash | K11: Central | L11: Premium | M11: 44460 | N11: 1199.96
A12: TRX0046 | B12: 45646 | C12: CUST003 | D12: Michael Brown | E12: P008 | F12: Bookshelf | G12: Furniture | H12: 2 | I12: 149.99 | J12: Cash | K12: South | L12: Basic | M12: 45239 | N12: 299.98
A13: TRX0143 | B13: 45654 | C13: CUST003 | D13: Michael Brown | E13: P007 | F13: Desk | G13: Furniture | H13: 2 | I13: 299.99 | J13: Cash | K13: West | L13: Basic | M13: 44771 | N13: 599.98
... A251: TRX0093 | B251: 45452 | C251: CUST050 | D251: Julie Foster | E251: P005 | F251: Blender | G251: Appliances | H251: 4 | I251: 59.99 | J251: Cash | K251: East | L251: Standard | M251: 44435 | N251: 239.96

Sheet Date_Time
A1: DATE & TIME FUNCTIONS .
A3: TODAY(), NOW(), DATEDIF(), EOMONTH().
A5: Current Date (TODAY) | B5: =TODAY() -> 46129
A6: Current Date & Time (NOW) | B6: =NOW() -> 46129.422
A7: Day's Since Customer Join (DATEDIF) | B7: =DATEDIF(Dataset!M2,TODAY(),"Y") -> 4
A8: End of Current Month (EOMONTH) | B8: =EOMONTH(Dataset!B2,0) -> 45747

Sheet Filter_Function
A1: FILTER FUNCTION
B4: 1. FILTER (Electronics Categories Product) | K4: 2. FILTER(Furnitures Categories Product) | T4: 3.FILTER(Premium Segment Customers)
B5: Customers_ID | C5: Customers_Name | D5: =Table1[[#Headers],[Product_ID]] -> Product_ID | E5: =Table1[[#Headers],[Product_Name]] -> Product_Name | F5: =Table1[[#Headers],[Category]] -> Category | G5: =Table1[[#Headers],[Quantity]] -> Quantity | H5: =Table1[[#Headers],[Total_Amount]] -> Total_Amount | K5: Customers_ID | L5: Customers_Name | M5: =Table1[[#Headers],[Product_ID]] -> Product_ID | N5: =Table1[[#Headers],[Product_Name]] -> Product_Name | O5: =Table1[[#Headers],[Category]] -> Category | P5: =Table1[[#Headers],[Quantity]] -> Quantity | Q5: =Table1[[#Headers],[Total_Amount]] -> Total_Amount | T5: =Table1[[#Headers],[Transaction_ID]] -> Transaction_ID | U5: =Table1[[#Headers],[Date]] -> Date | V5: =Table1[[#Headers],[Customer_ID]] -> Customer_ID | W5: =Table1[[#Headers],[Customer_Name]] -> Customer_Name | X5: =Table1[[#Headers],[Product_ID]] -> Product_ID | Y5: =Table1[[#Headers],[Product_Name]] -> Product_Name | Z5: =Table1[[#Headers],[Category]] -> Category | AA5: =Table1[[#Headers],[Quantity]] -> Quantity | AB5: =Table1[[#Headers],[Unit_Price]] -> Unit_Price | AC5: =Table1[[#Headers],[Payment_Method]] -> Payment_Method | AD5: =Table1[[#Headers],[Region]] -> Region | AE5: =Table1[[#Headers],[Customer_Segment]] -> Customer_Segment | AF5: =Table1[[#Headers],[Customer_Since]] -> Customer_Since | AG5: =Table1[[#Headers],[Total_Amount]] -> Total_Amount
B6: {=_xlfn._xlws.FILTER(_xlfn.HSTACK(Table1[Customer_ID], Table1[Customer_Name], Table1[Product_ID], Table1[Product_Name], Table1[Category], Table1[Quantity], Table1[Total_Amount]), Table1[Category]="Electronics", "Not Found")} -> CUST002 | C6: Emma Wilson | D6: P010 | E6: Keyboard | F6: Electronics | G6: 2 | H6: 179.98 | K6: {=_xlfn._xlws.FILTER(_xlfn.HSTACK(Table1[Customer_ID],Table1[Customer_Name],Table1[Product_ID],Table1[Product_Name],Table1[Category],Table1[Quantity],Table1[Total_Amount]),Table1[Category]="Furniture","Not Found")} -> CUST001 | L6: John Smith | M6: P008 | N6: Bookshelf | O6: Furniture | P6: 4 | Q6: 599.96 | T6: {=_xlfn._xlws.FILTER(Table1[],Table1[Customer_Segment]="Premium")} -> TRX0130 | U6: 45430 | V6: CUST002 | W6: Emma Wilson | X6: P008 | Y6: Bookshelf | Z6: Furniture | AA6: 3 | AB6: 149.99 | AC6: Credit Card | AD6: West | AE6: Premium | AF6: 45068 | AG6: 449.97
B7: CUST003 | C7: Michael Brown | D7: P002 | E7: Smartphone | F7: Electronics | G7: 2 | H7: 1399.98 | K7: CUST002 | L7: Emma Wilson | M7: P008 | N7: Bookshelf | O7: Furniture | P7: 3 | Q7: 449.97 | T7: TRX0096 | U7: 45474 | V7: CUST002 | W7: Emma Wilson | X7: P010 | Y7: Keyboard | Z7: Electronics | AA7: 2 | AB7: 89.99 | AC7: PayPal | AD7: Central | AE7: Premium | AF7: 45275 | AG7: 179.98
B8: CUST003 | C8: Michael Brown | D8: P010 | E8: Keyboard | F8: Electronics | G8: 3 | H8: 269.97 | K8: CUST002 | L8: Emma Wilson | M8: P008 | N8: Bookshelf | O8: Furniture | P8: 2 | Q8: 299.98 | T8: TRX0003 | U8: 45737 | V8: CUST002 | W8: Emma Wilson | X8: P008 | Y8: Bookshelf | Z8: Furniture | AA8: 2 | AB8: 149.99 | AC8: Cash | AD8: West | AE8: Premium | AF8: 45233 | AG8: 299.98
B9: CUST004 | C9: Sarah Davis | D9: P010 | E9: Keyboard | F9: Electronics | G9: 5 | H9: 449.95 | K9: CUST003 | L9: Michael Brown | M9: P008 | N9: Bookshelf | O9: Furniture | P9: 5 | Q9: 749.95 | T9: TRX0212 | U9: 45400 | V9: CUST003 | W9: Michael Brown | X9: P008 | Y9: Bookshelf | Z9: Furniture | AA9: 5 | AB9: 149.99 | AC9: Credit Card | AD9: North | AE9: Premium | AF9: 45295 | AG9: 749.95
B10: CUST004 | C10: Sarah Davis | D10: P002 | E10: Smartphone | F10: Electronics | G10: 2 | H10: 1399.98 | K10: CUST003 | L10: Michael Brown | M10: P008 | N10: Bookshelf | O10: Furniture | P10: 2 | Q10: 299.98 | T10: TRX0220 | U10: 45450 | V10: CUST003 | W10: Michael Brown | X10: P008 | Y10: Bookshelf | Z10: Furniture | AA10: 2 | AB10: 149.99 | AC10: Cash | AD10: East | AE10: Premium | AF10: 44645 | AG10: 299.98
B11: CUST004 | C11: Sarah Davis | D11: P002 | E11: Smartphone | F11: Electronics | G11: 3 | H11: 2099.97 | K11: CUST003 | L11: Michael Brown | M11: P007 | N11: Desk | O11: Furniture | P11: 4 | Q11: 1199.96 | T11: TRX0113 | U11: 45481 | V11: CUST003 | W11: Michael Brown | X11: P002 | Y11: Smartphone | Z11: Electronics | AA11: 2 | AB11: 699.99 | AC11: PayPal | AD11: East | AE11: Premium | AF11: 45389 | AG11: 1399.98
B12: CUST006 | C12: Lisa Anderson | D12: P010 | E12: Keyboard | F12: Electronics | G12: 5 | H12: 449.95 | K12: CUST003 | L12: Michael Brown | M12: P008 | N12: Bookshelf | O12: Furniture | P12: 2 | Q12: 299.98 | T12: TRX0174 | U12: 45566 | V12: CUST003 | W12: Michael Brown | X12: P007 | Y12: Desk | Z12: Furniture | AA12: 4 | AB12: 299.99 | AC12: Cash | AD12: Central | AE12: Premium | AF12: 44460 | AG12: 1199.96
B13: CUST006 | C13: Lisa Anderson | D13: P003 | E13: Headphones | F13: Electronics | G13: 5 | H13: 749.95 | K13: CUST003 | L13: Michael Brown | M13: P007 | N13: Desk | O13: Furniture | P13: 2 | Q13: 599.98 | T13: TRX0166 | U13: 45688 | V13: CUST003 | W13: Michael Brown | X13: P010 | Y13: Keyboard | Z13: Electronics | AA13: 3 | AB13: 89.99 | AC13: Debit Card | AD13: South | AE13: Premium | AF13: 45307 | AG13: 269.97
B14: CUST007 | C14: David Martinez | D14: P003 | E14: Headphones | F14: Electronics | G14: 4 | H14: 599.96 | K14: CUST003 | L14: Michael Brown | M14: P007 | N14: Desk | O14: Furniture | P14: 3 | Q14: 899.97 | T14: TRX0082 | U14: 45635 | V14: CUST005 | W14: James Johnson | X14: P005 | Y14: Blender | Z14: Appliances | AA14: 3 | AB14: 59.99 | AC14: Cash | AD14: Central | AE14: Premium | AF14: 45052 | AG14: 179.97
B15: CUST007 | C15: David Martinez | D15: P010 | E15: Keyboard | F15: Electronics | G15: 1 | H15: 89.99 | K15: CUST003 | L15: Michael Brown | M15: P008 | N15: Bookshelf | O15: Furniture | P15: 3 | Q15: 449.97 | T15: TRX0088 | U15: 45456 | V15: CUST006 | W15: Lisa Anderson | X15: P010 | Y15: Keyboard | Z15: Electronics | AA15: 5 | AB15: 89.99 | AC15: Cash | AD15: Central | AE15: Premium | AF15: 44579 | AG15: 449.95
B16: CUST008 | C16: Jennifer Taylor | D16: P002 | E16: Smartphone | F16: Electronics | G16: 5 | H16: 3499.95 | K16: CUST004 | L16: Sarah Davis | M16: P006 | N16: Office Chair | O16: Furniture | P16: 4 | Q16: 799.96 | T16: TRX0237 | U16: 45663 | V16: CUST006 | W16: Lisa Anderson | X16: P003 | Y16: Headphones | Z16: Electronics | AA16: 5 | AB16: 149.99 | AC16: PayPal | AD16: East | AE16: Premium | AF16: 44824 | AG16: 749.95
B17: CUST009 | C17: Robert Thomas | D17: P001 | E17: Laptop | F17: Electronics | G17: 3 | H17: 2699.97 | K17: CUST004 | L17: Sarah Davis | M17: P008 | N17: Bookshelf | O17: Furniture | P17: 5 | Q17: 749.95 | T17: TRX0020 | U17: 45517 | V17: CUST007 | W17: David Martinez | X17: P003 | Y17: Headphones | Z17: Electronics | AA17: 4 | AB17: 149.99 | AC17: Debit Card | AD17: South | AE17: Premium | AF17: 44820 | AG17: 599.96
B18: CUST009 | C18: Robert Thomas | D18: P010 | E18: Keyboard | F18: Electronics | G18: 2 | H18: 179.98 | K18: CUST006 | L18: Lisa Anderson | M18: P008 | N18: Bookshelf | O18: Furniture | P18: 2 | Q18: 299.98 | T18: TRX0156 | U18: 45655 | V18: CUST009 | W18: Robert Thomas | X18: P010 | Y18: Keyboard | Z18: Electronics | AA18: 1 | AB18: 89.99 | AC18: Credit Card | AD18: South | AE18: Premium | AF18: 44591 | AG18: 89.99
... B81: CUST028 | C81: Betty Campbell | D81: P002 | E81: Smartphone | F81: Electronics | G81: 5 | H81: 3499.95 | K81: CUST048 | L81: Virginia Sanders | M81: P008 | N81: Bookshelf | O81: Furniture | P81: 3 | Q81: 449.97 | T81: TRX0147 | U81: 45655 | V81: CUST036 | W81: Nancy Collins | X81: P008 | Y81: Bookshelf | Z81: Furniture | AA81: 5 | AB81: 149.99 | AC81: Cash | AD81: Central | AE81: Premium | AF81: 45347 | AG81: 749.95
B82: CUST028 | C82: Betty Campbell | D82: P009 | E82: Monitor | F82: Electronics | G82: 4 | H82: 999.96 | T82: TRX0187 | U82: 45701 | V82: CUST036 | W82: Nancy Collins | X82: P004 | Y82: Coffee Maker | Z82: Appliances | AA82: 3 | AB82: 79.99 | AC82: Cash | AD82: East | AE82: Premium | AF82: 44436 | AG82: 239.97
B83: CUST029 | C83: Edward Mitchell | D83: P001 | E83: Laptop | F83: Electronics | G83: 5 | H83: 4499.95 | T83: TRX0200 | U83: 45711 | V83: CUST037 | W83: Arthur Edwards | X83: P008 | Y83: Bookshelf | Z83: Furniture | AA83: 4 | AB83: 149.99 | AC83: PayPal | AD83: North | AE83: Premium | AF83: 44412 | AG83: 599.96
B84: CUST029 | C84: Edward Mitchell | D84: P010 | E84: Keyboard | F84: Electronics | G84: 2 | H84: 179.98 | T84: TRX0238 | U84: 45668 | V84: CUST038 | W84: Michelle Rogers | X84: P002 | Y84: Smartphone | Z84: Electronics | AA84: 3 | AB84: 699.99 | AC84: Cash | AD84: North | AE84: Premium | AF84: 44602 | AG84: 2099.97
B85: CUST029 | C85: Edward Mitchell | D85: P002 | E85: Smartphone | F85: Electronics | G85: 5 | H85: 3499.95 | T85: TRX0001 | U85: 45528 | V85: CUST039 | W85: Lawrence Reed | X85: P004 | Y85: Coffee Maker | Z85: Appliances | AA85: 3 | AB85: 79.99 | AC85: Cash | AD85: Central | AE85: Premium | AF85: 44779 | AG85: 239.97
B86: CUST029 | C86: Edward Mitchell | D86: P001 | E86: Laptop | F86: Electronics | G86: 3 | H86: 2699.97 | T86: TRX0225 | U86: 45538 | V86: CUST039 | W86: Lawrence Reed | X86: P002 | Y86: Smartphone | Z86: Electronics | AA86: 2 | AB86: 699.99 | AC86: Debit Card | AD86: Central | AE86: Premium | AF86: 44870 | AG86: 1399.98
B87: CUST030 | C87: Helen Roberts | D87: P001 | E87: Laptop | F87: Electronics | G87: 4 | H87: 3599.96 | T87: TRX0226 | U87: 45720 | V87: CUST039 | W87: Lawrence Reed | X87: P002 | Y87: Smartphone | Z87: Electronics | AA87: 5 | AB87: 699.99 | AC87: Debit Card | AD87: East | AE87: Premium | AF87: 45161 | AG87: 3499.95
B88: CUST030 | C88: Helen Roberts | D88: P003 | E88: Headphones | F88: Electronics | G88: 2 | H88: 299.98 | T88: TRX0186 | U88: 45724 | V88: CUST039 | W88: Lawrence Reed | X88: P008 | Y88: Bookshelf | Z88: Furniture | AA88: 2 | AB88: 149.99 | AC88: PayPal | AD88: Central | AE88: Premium | AF88: 44632 | AG88: 299.98
B89: CUST030 | C89: Helen Roberts | D89: P009 | E89: Monitor | F89: Electronics | G89: 5 | H89: 1249.95 | T89: TRX0124 | U89: 45737 | V89: CUST040 | W89: Sharon Butler | X89: P001 | Y89: Laptop | Z89: Electronics | AA89: 3 | AB89: 899.99 | AC89: Debit Card | AD89: North | AE89: Premium | AF89: 44876 | AG89: 2699.97
B90: CUST031 | C90: Steven Turner | D90: P003 | E90: Headphones | F90: Electronics | G90: 4 | H90: 599.96 | T90: TRX0246 | U90: 45408 | V90: CUST041 | W90: Peter Richardson | X90: P008 | Y90: Bookshelf | Z90: Furniture | AA90: 3 | AB90: 149.99 | AC90: Cash | AD90: North | AE90: Premium | AF90: 44806 | AG90: 449.97
B91: CUST031 | C91: Steven Turner | D91: P010 | E91: Keyboard | F91: Electronics | G91: 3 | H91: 269.97 | T91: TRX0216 | U91: 45490 | V91: CUST041 | W91: Peter Richardson | X91: P008 | Y91: Bookshelf | Z91: Furniture | AA91: 3 | AB91: 149.99 | AC91: Cash | AD91: Central | AE91: Premium | AF91: 45199 | AG91: 449.97
B92: CUST032 | C92: Sandra Phillips | D92: P002 | E92: Smartphone | F92: Electronics | G92: 2 | H92: 1399.98 | T92: TRX0024 | U92: 45695 | V92: CUST042 | W92: Ruth Brooks | X92: P008 | Y92: Bookshelf | Z92: Furniture | AA92: 3 | AB92: 149.99 | AC92: Debit Card | AD92: North | AE92: Premium | AF92: 44564 | AG92: 449.97
B93: CUST032 | C93: Sandra Phillips | D93: P001 | E93: Laptop | F93: Electronics | G93: 3 | H93: 2699.97 | T93: TRX0047 | U93: 45711 | V93: CUST042 | W93: Ruth Brooks | X93: P002 | Y93: Smartphone | Z93: Electronics | AA93: 1 | AB93: 699.99 | AC93: Cash | AD93: North | AE93: Premium | AF93: 44583 | AG93: 699.99
... B100: CUST035 | C100: Harry Morgan | D100: P009 | E100: Monitor | F100: Electronics | G100: 1 | H100: 249.99 | T100: TRX0222 | U100: 45410 | V100: CUST048 | W100: Virginia Sanders | X100: P009 | Y100: Monitor | Z100: Electronics | AA100: 3 | AB100: 249.99 | AC100: Credit Card | AD100: North | AE100: Premium | AF100: 45224 | AG100: 749.97
B101: CUST036 | C101: Nancy Collins | D101: P009 | E101: Monitor | F101: Electronics | G101: 5 | H101: 1249.95
B102: CUST036 | C102: Nancy Collins | D102: P003 | E102: Headphones | F102: Electronics | G102: 3 | H102: 449.97
B103: CUST036 | C103: Nancy Collins | D103: P009 | E103: Monitor | F103: Electronics | G103: 2 | H103: 499.98
B104: CUST037 | C104: Arthur Edwards | D104: P001 | E104: Laptop | F104: Electronics | G104: 1 | H104: 899.99
B105: CUST038 | C105: Michelle Rogers | D105: P002 | E105: Smartphone | F105: Electronics | G105: 3 | H105: 2099.97
B106: CUST038 | C106: Michelle Rogers | D106: P002 | E106: Smartphone | F106: Electronics | G106: 3 | H106: 2099.97
B107: CUST039 | C107: Lawrence Reed | D107: P002 | E107: Smartphone | F107: Electronics | G107: 2 | H107: 1399.98
B108: CUST039 | C108: Lawrence Reed | D108: P003 | E108: Headphones | F108: Electronics | G108: 2 | H108: 299.98
B109: CUST039 | C109: Lawrence Reed | D109: P010 | E109: Keyboard | F109: Electronics | G109: 3 | H109: 269.97
B110: CUST039 | C110: Lawrence Reed | D110: P002 | E110: Smartphone | F110: Electronics | G110: 5 | H110: 3499.95
...

Sheet Conditional_Formatting
B2: Conditional Formattaing
B3: Transaction ID | C3: Customer Name | D3: Amount | E3: Trend
B4: {=_xlfn.UNIQUE(Table1[Transaction_ID])} -> TRX0050 | C4: {=_xlfn.XLOOKUP(_xlfn.ANCHORARRAY(B4), Table1[Transaction_ID], Table1[Customer_Name])} -> John Smith | D4: {=_xlfn.XLOOKUP(_xlfn.ANCHORARRAY(B4), Table1[Transaction_ID], Table1[Total_Amount])} -> 599.96 | E4: =IF(D4>3000,"▲",IF(D4=1500,"►","▼")) -> ▼
B5: TRX0130 | C5: Emma Wilson | D5: 449.97 | E5: =IF(D5>3000,"▲",IF(D5=1500,"►","▼")) -> ▼
B6: TRX0096 | C6: Emma Wilson | D6: 179.98 | E6: =IF(D6>3000,"▲",IF(D6=1500,"►","▼")) -> ▼
B7: TRX0142 | C7: Emma Wilson | D7: 179.97 | E7: =IF(D7>3000,"▲",IF(D7=1500,"►","▼")) -> ▼
B8: TRX0028 | C8: Emma Wilson | D8: 119.98 | E8: =IF(D8>3000,"▲",IF(D8=1500,"►","▼")) -> ▼
B9: TRX0003 | C9: Emma Wilson | D9: 299.98 | E9: =IF(D9>3000,"▲",IF(D9=1500,"►","▼")) -> ▼
B10: TRX0212 | C10: Michael Brown | D10: 749.95 | E10: =IF(D10>3000,"▲",IF(D10=1500,"►","▼")) -> ▼
B11: TRX0220 | C11: Michael Brown | D11: 299.98 | E11: =IF(D11>3000,"▲",IF(D11=1500,"►","▼")) -> ▼
B12: TRX0113 | C12: Michael Brown | D12: 1399.98 | E12: =IF(D12>3000,"▲",IF(D12=1500,"►","▼")) -> ▼
B13: TRX0174 | C13: Michael Brown | D13: 1199.96 | E13: =IF(D13>3000,"▲",IF(D13=1500,"►","▼")) -> ▼
B14: TRX0046 | C14: Michael Brown | D14: 299.98 | E14: =IF(D14>3000,"▲",IF(D14=1500,"►","▼")) -> ▼
B15: TRX0143 | C15: Michael Brown | D15: 599.98 | E15: =IF(D15>3000,"▲",IF(D15=1500,"►","▼")) -> ▼
B16: TRX0091 | C16: Michael Brown | D16: 899.97 | E16: =IF(D16>3000,"▲",IF(D16=1500,"►","▼")) -> ▼
... B253: TRX0093 | C253: Julie Foster | D253: 239.96 | E253: =IF(D253>3000,"▲",IF(D253=1500,"►","▼")) -> ▼

Sheet What_if_Analysis
A1: WHAT IF ANALYSIS
A3: SCENARIO MANAGER
A5: Current Average Transaction | B5: =AVERAGE(Table1[Total_Amount]) -> 916.76988
A7: Price Percentage of Increase/Discrease | B7: 0.15
A8: New Average Transaction | B8: =B5*(1+B7) -> 1054.2854
A9: Projected Total Revenue | B9: =B8*COUNTA(Table1[Transaction_ID]) -> 263571.34
A12: GOAL SEEK
A14: Target Revenue | B14: 350000
A15: Percentage off required | B15: 380.7752
A16: New Transaction Value | B16: =B5*(1+B15) -> 350000

Sheet Linear_Regression
B2: LINEAR REGRESSION | E2: PREDICTION TOTAL AMOUNT
B3: SLOPE | C3: =SLOPE(Table1[Total_Amount],Table1[Quantity]) -> 353.793 | E3: Qunatity | G3: Predicted Amount
B4: INTERCEPT | C4: =INTERCEPT(Table1[Total_Amount],Table1[Quantity]) -> -148.85465 | E4: 1 | G4: =C3*E4+C4 -> 204.93836
B5: R-Squared (RSQ) | C5: =RSQ(Table1[Total_Amount],Table1[Quantity]) -> 0.20983762 | E5: 2 | G5: =C3*E5+C4 -> 558.73136
B6: CORREL | C6: =CORREL(Table1[Total_Amount],Table1[Quantity]) -> 0.45808036 | E6: 3 | G6: =C3*E6+C4 -> 912.52436
E7: 4 | G7: =C3*E7+C4 -> 1266.3174
E8: 5 | G8: =C3*E8+C4 -> 1620.1104
B11: SUMMARY OUTPUT
B13: Regression Statistics
B14: Multiple R | C14: 0.45808036
B15: R Square | C15: 0.20983762
B16: Adjusted R Square | C16: 0.20665148
B17: Standard Error | C17: 919.60715
B18: Observations | C18: 250
B20: ANOVA
C21: df | D21: SS | E21: MS | F21: F | G21: Significance F
B22: Regression | C22: 1 | D22: 55695917 | E22: 55695917 | F22: 65.859537 | G22: 2.2586479e-14
B23: Residual | C23: 248 | D23: 2.0972797e+08 | E23: 845677.32
B24: Total | C24: 249 | D24: 2.6542389e+08
C26: Coefficients | D26: Standard Error | E26: t Stat | F26: P-value | G26: Lower 95% | H26: Upper 95% | I26: Lower 95.0% | J26: Upper 95.0%
B27: Intercept | C27: -148.85465 | D27: 143.61334 | E27: -1.0364959 | F27: 0.3009804 | G27: -431.712 | H27: 134.0027 | I27: -431.712 | J27: 134.0027
B28: X Variable 1 | C28: 353.793 | D28: 43.595323 | E28: 8.1153889 | F28: 2.2586479e-14 | G28: 267.92872 | H28: 439.65729 | I28: 267.92872 | J28: 439.65729

Sheet High_Value_Customers
A1: 📶 High Value Customers
B2: {=_xlfn.UNIQUE(Table1[Customer_Name])} -> John Smith | C2: =SUMIFS(Table1[Total_Amount],Table1[Customer_Name],High_Value_Customers!B2) -> 599.96 | D2: =IF(C2>=1000,"High-Value","Normal-Value") -> Normal-Value
B3: Emma Wilson | C3: =SUMIFS(Table1[Total_Amount],Table1[Customer_Name],High_Value_Customers!B3) -> 1229.88 | D3: =IF(C3>=1000,"High-Value","Normal-Value") -> High-Value
B4: Michael Brown | C4: =SUMIFS(Table1[Total_Amount],Table1[Customer_Name],High_Value_Customers!B4) -> 6169.74 | D4: =IF(C4>=1000,"High-Value","Normal-Value") -> High-Value
B5: Sarah Davis | C5: =SUMIFS(Table1[Total_Amount],Table1[Customer_Name],High_Value_Customers!B5) -> 5499.81 | D5: =IF(C5>=1000,"High-Value","Normal-Value") -> High-Value
B6: James Johnson | C6: =SUMIFS(Table1[Total_Amount],Table1[Customer_Name],High_Value_Customers!B6) -> 179.97 | D6: =IF(C6>=1000,"High-Value","Normal-Value") -> Normal-Value
B7: Lisa Anderson | C7: =SUMIFS(Table1[Total_Amount],Table1[Customer_Name],High_Value_Customers!B7) -> 2039.8 | D7: =IF(C7>=1000,"High-Value","Normal-Value") -> High-Value
B8: David Martinez | C8: =SUMIFS(Table1[Total_Amount],Table1[Customer_Name],High_Value_Customers!B8) -> 1809.84 | D8: =IF(C8>=1000,"High-Value","Normal-Value") -> High-Value
B9: Jennifer Taylor | C9: =SUMIFS(Table1[Total_Amount],Table1[Customer_Name],High_Value_Customers!B9) -> 4739.85 | D9: =IF(C9>=1000,"High-Value","Normal-Value") -> High-Value
B10: Robert Thomas | C10: =SUMIFS(Table1[Total_Amount],Table1[Customer_Name],High_Value_Customers!B10) -> 3509.9 | D10: =IF(C10>=1000,"High-Value","Normal-Value") -> High-Value
B11: Maria Garcia | C11: =SUMIFS(Table1[Total_Amount],Table1[Customer_Name],High_Value_Customers!B11) -> 1909.93 | D11: =IF(C11>=1000,"High-Value","Normal-Value") -> High-Value
B12: William White | C12: =SUMIFS(Table1[Total_Amount],Table1[Customer_Name],High_Value_Customers!B12) -> 4749.91 | D12: =IF(C12>=1000,"High-Value","Normal-Value") -> High-Value
B13: Patricia Moore | C13: =SUMIFS(Table1[Total_Amount],Table1[Customer_Name],High_Value_Customers!B13) -> 9799.73 | D13: =IF(C13>=1000,"High-Value","Normal-Value") -> High-Value
B14: Joseph Jackson | C14: =SUMIFS(Table1[Total_Amount],Table1[Customer_Name],High_Value_Customers!B14) -> 6949.84 | D14: =IF(C14>=1000,"High-Value","Normal-Value") -> High-Value
... B51: Julie Foster | C51: =SUMIFS(Table1[Total_Amount],Table1[Customer_Name],High_Value_Customers!B51) -> 239.96 | D51: =IF(C51>=1000,"High-Value","Normal-Value") -> Normal-Value

Sheet Product_Analysis
B3: Product ID | C3: Product Name | D3: Category | E3: Total Revenue | F3: Units Sold | G3: Transaction | H3: Avg Price | J3: Most frequently purchased product
B4: {=_xlfn._xlws.SORT(_xlfn.UNIQUE(Table1[[Product_ID]:[Category]]))} -> P001 | C4: Laptop | D4: Electronics | E4: =SUMIFS(Table1[Total_Amount],Table1[Product_ID],Product_Analysis!B4) -> 67499.25 | F4: =SUMIFS(Table1[Quantity],Table1[Product_ID],Product_Analysis!B4) -> 75 | G4: =COUNTIFS(Table1[Product_ID],Product_Analysis!B4) -> 24 | H4: =AVERAGEIFS(Table1[Unit_Price],Table1[Product_ID],Product_Analysis!B4) -> 899.99 | J4: {=INDEX(Table1[Product_Name],_xlfn.MODE.SNGL(MATCH(Table1[Product_Name],Table1[Product_Name],0)))} -> Bookshelf
B5: P002 | C5: Smartphone | D5: Electronics | E5: =SUMIFS(Table1[Total_Amount],Table1[Product_ID],Product_Analysis!B5) -> 67199.04 | F5: =SUMIFS(Table1[Quantity],Table1[Product_ID],Product_Analysis!B5) -> 96 | G5: =COUNTIFS(Table1[Product_ID],Product_Analysis!B5) -> 31 | H5: =AVERAGEIFS(Table1[Unit_Price],Table1[Product_ID],Product_Analysis!B5) -> 699.99
B6: P003 | C6: Headphones | D6: Electronics | E6: =SUMIFS(Table1[Total_Amount],Table1[Product_ID],Product_Analysis!B6) -> 7049.53 | F6: =SUMIFS(Table1[Quantity],Table1[Product_ID],Product_Analysis!B6) -> 47 | G6: =COUNTIFS(Table1[Product_ID],Product_Analysis!B6) -> 16 | H6: =AVERAGEIFS(Table1[Unit_Price],Table1[Product_ID],Product_Analysis!B6) -> 149.99
B7: P004 | C7: Coffee Maker | D7: Appliances | E7: =SUMIFS(Table1[Total_Amount],Table1[Product_ID],Product_Analysis!B7) -> 3119.61 | F7: =SUMIFS(Table1[Quantity],Table1[Product_ID],Product_Analysis!B7) -> 39 | G7: =COUNTIFS(Table1[Product_ID],Product_Analysis!B7) -> 14 | H7: =AVERAGEIFS(Table1[Unit_Price],Table1[Product_ID],Product_Analysis!B7) -> 79.99
B8: P005 | C8: Blender | D8: Appliances | E8: =SUMIFS(Table1[Total_Amount],Table1[Product_ID],Product_Analysis!B8) -> 5219.13 | F8: =SUMIFS(Table1[Quantity],Table1[Product_ID],Product_Analysis!B8) -> 87 | G8: =COUNTIFS(Table1[Product_ID],Product_Analysis!B8) -> 29 | H8: =AVERAGEIFS(Table1[Unit_Price],Table1[Product_ID],Product_Analysis!B8) -> 59.99
B9: P006 | C9: Office Chair | D9: Furniture | E9: =SUMIFS(Table1[Total_Amount],Table1[Product_ID],Product_Analysis!B9) -> 10399.48 | F9: =SUMIFS(Table1[Quantity],Table1[Product_ID],Product_Analysis!B9) -> 52 | G9: =COUNTIFS(Table1[Product_ID],Product_Analysis!B9) -> 15 | H9: =AVERAGEIFS(Table1[Unit_Price],Table1[Product_ID],Product_Analysis!B9) -> 199.99
B10: P007 | C10: Desk | D10: Furniture | E10: =SUMIFS(Table1[Total_Amount],Table1[Product_ID],Product_Analysis!B10) -> 23399.22 | F10: =SUMIFS(Table1[Quantity],Table1[Product_ID],Product_Analysis!B10) -> 78 | G10: =COUNTIFS(Table1[Product_ID],Product_Analysis!B10) -> 26 | H10: =AVERAGEIFS(Table1[Unit_Price],Table1[Product_ID],Product_Analysis!B10) -> 299.99
B11: P008 | C11: Bookshelf | D11: Furniture | E11: =SUMIFS(Table1[Total_Amount],Table1[Product_ID],Product_Analysis!B11) -> 15298.98 | F11: =SUMIFS(Table1[Quantity],Table1[Product_ID],Product_Analysis!B11) -> 102 | G11: =COUNTIFS(Table1[Product_ID],Product_Analysis!B11) -> 35 | H11: =AVERAGEIFS(Table1[Unit_Price],Table1[Product_ID],Product_Analysis!B11) -> 149.99
B12: P009 | C12: Monitor | D12: Electronics | E12: =SUMIFS(Table1[Total_Amount],Table1[Product_ID],Product_Analysis!B12) -> 21999.12 | F12: =SUMIFS(Table1[Quantity],Table1[Product_ID],Product_Analysis!B12) -> 88 | G12: =COUNTIFS(Table1[Product_ID],Product_Analysis!B12) -> 26 | H12: =AVERAGEIFS(Table1[Unit_Price],Table1[Product_ID],Product_Analysis!B12) -> 249.99
B13: P010 | C13: Keyboard | D13: Electronics | E13: =SUMIFS(Table1[Total_Amount],Table1[Product_ID],Product_Analysis!B13) -> 8009.11 | F13: =SUMIFS(Table1[Quantity],Table1[Product_ID],Product_Analysis!B13) -> 89 | G13: =COUNTIFS(Table1[Product_ID],Product_Analysis!B13) -> 34 | H13: =AVERAGEIFS(Table1[Unit_Price],Table1[Product_ID],Product_Analysis!B13) -> 89.99

Sheet Regional_Analysis
B2: Region | C2: Total Revenue | D2: Transactions | E2: Unique Customers
B3: {=_xlfn.UNIQUE(Table1[Region])} -> West | C3: =SUMIFS(Table1[Total_Amount],Table1[Region],Regional_Analysis!B3) -> 41408.68 | D3: =COUNTIFS(Table1[Region],Regional_Analysis!B3) -> 47 | E3: {=COUNTA(_xlfn.UNIQUE(_xlfn._xlws.FILTER(Table1[Customer_Name], Table1[Region]=B3)))} -> 30
B4: Central | C4: =SUMIFS(Table1[Total_Amount],Table1[Region],Regional_Analysis!B4) -> 41288.34 | D4: =COUNTIFS(Table1[Region],Regional_Analysis!B4) -> 54 | E4: {=COUNTA(_xlfn.UNIQUE(_xlfn._xlws.FILTER(Table1[Customer_Name], Table1[Region]=B4)))} -> 32
B5: East | C5: =SUMIFS(Table1[Total_Amount],Table1[Region],Regional_Analysis!B5) -> 59288.39 | D5: =COUNTIFS(Table1[Region],Regional_Analysis!B5) -> 48 | E5: {=COUNTA(_xlfn.UNIQUE(_xlfn._xlws.FILTER(Table1[Customer_Name], Table1[Region]=B5)))} -> 29
B6: North | C6: =SUMIFS(Table1[Total_Amount],Table1[Region],Regional_Analysis!B6) -> 50808.31 | D6: =COUNTIFS(Table1[Region],Regional_Analysis!B6) -> 59 | E6: {=COUNTA(_xlfn.UNIQUE(_xlfn._xlws.FILTER(Table1[Customer_Name], Table1[Region]=B6)))} -> 31
B7: South | C7: =SUMIFS(Table1[Total_Amount],Table1[Region],Regional_Analysis!B7) -> 36398.75 | D7: =COUNTIFS(Table1[Region],Regional_Analysis!B7) -> 42 | E7: {=COUNTA(_xlfn.UNIQUE(_xlfn._xlws.FILTER(Table1[Customer_Name], Table1[Region]=B7)))} -> 29
B8: Total | C8: =SUM(C3:C7) -> 229192.47 | D8: =SUM(D3:D7) -> 250

Sheet Abbrevation
A1: ABBREVIATION FUNCTION
B3: CUSTOMER ABBREVIATION (TEXT FUNCTION)
B5: Full Name | C5: Abbreviation
B6: {=_xlfn.UNIQUE(Table1[Customer_Name])} -> John Smith | C6: =LEFT(B6,1)&MID(B6,FIND(" ",B6)+1,1) -> JS
B7: Emma Wilson | C7: =LEFT(B7,1)&MID(B7,FIND(" ",B7)+1,1) -> EW
B8: Michael Brown | C8: =LEFT(B8,1)&MID(B8,FIND(" ",B8)+1,1) -> MB
B9: Sarah Davis | C9: =LEFT(B9,1)&MID(B9,FIND(" ",B9)+1,1) -> SD
B10: James Johnson | C10: =LEFT(B10,1)&MID(B10,FIND(" ",B10)+1,1) -> JJ
B11: Lisa Anderson | C11: =LEFT(B11,1)&MID(B11,FIND(" ",B11)+1,1) -> LA
B12: David Martinez | C12: =LEFT(B12,1)&MID(B12,FIND(" ",B12)+1,1) -> DM
B13: Jennifer Taylor | C13: =LEFT(B13,1)&MID(B13,FIND(" ",B13)+1,1) -> JT
B14: Robert Thomas | C14: =LEFT(B14,1)&MID(B14,FIND(" ",B14)+1,1) -> RT
B15: Maria Garcia | C15: =LEFT(B15,1)&MID(B15,FIND(" ",B15)+1,1) -> MG
B16: William White | C16: =LEFT(B16,1)&MID(B16,FIND(" ",B16)+1,1) -> WW
B17: Patricia Moore | C17: =LEFT(B17,1)&MID(B17,FIND(" ",B17)+1,1) -> PM
B18: Joseph Jackson | C18: =LEFT(B18,1)&MID(B18,FIND(" ",B18)+1,1) -> JJ
... B55: Julie Foster | C55: =LEFT(B55,1)&MID(B55,FIND(" ",B55)+1,1) -> JF

Sheet KPI's
A2: KEY PERFORMANCE INDICATOR
A4: Total Revenue | B4: =SUM(Table1[Total_Amount]) -> 229192.47
A5: Total Transactions | B5: =COUNTA(Table1[Transaction_ID]) -> 250
A6: Average Order Value | B6: =B4/B5 -> 916.76988
A7: Total Unique Customers | B7: =COUNTA(_xlfn.UNIQUE(Table1[Customer_ID])) -> 50
A8: Total Units Sold | B8: =SUM(Table1[Quantity]) -> 753

Sheet Pivot_and_Charts
A3: Months (Date) | B3: Years (Date) | C3: Sum of Total_Amount | E3: Category | F3: Sum of Total_Amount | I3: Region | J3: Sum of Total_Amount | L3: Customer_Segment | M3: Sum of Total_Amount | O3: Payment_Method | P3: Count of Transaction_ID
A4: Jan | C4: 25799.15 | E4: Appliances | F4: 8338.74 | I4: Central | J4: 41288.34 | L4: Premium | M4: 0.3693713 | O4: Cash | P4: 76
A5: Feb | C5: 16069.38 | E5: Electronics | F5: 171756.05 | I5: East | J5: 59288.39 | L5: Standard | M5: 0.3593379 | O5: Credit Card | P5: 68
A6: Mar | C6: 19899.38 | E6: Furniture | F6: 49097.68 | I6: North | J6: 50808.31 | L6: Basic | M6: 0.27129081 | O6: Debit Card | P6: 54
A7: Apr | C7: 27899.16 | E7: Grand Total | F7: 229192.47 | I7: South | J7: 36398.75 | L7: Grand Total | M7: 1 | O7: PayPal | P7: 52
A8: May | C8: 17039.35 | I8: West | J8: 41408.68 | O8: Grand Total | P8: 250
A9: Jun | C9: 19299.45 | I9: Grand Total | J9: 229192.47
A10: Jul | C10: 18479.4
A11: Aug | C11: 15759.43
A12: Sep | C12: 12989.51
A13: Oct | C13: 20609.52
A14: Nov | C14: 12309.44
A15: Dec | C15: 23039.3
A16: Grand Total | C16: 229192.47

Sheet Dashboard
